# 4장 콜백함수

### 콜백함수

콜백함수란 다른 코드의 인자로 넘겨주는 함수이다.

**회신되는 함수라고 생각하면 된다!**

**콜백함수의 특징**

- 다른 함수(A)의 인자로 콜백함수(B)를 전달하면, A가 B의 제어권을 가지게된다..
- 여기서 제어권이란 (실행시점, 매개변수, this) 이 세가지를 말한다.
- 특별한 요청(bind)이 없는 한 A가 미리 정해놓은 방식에 따라 B를 호출한다.
- 미리 정해놓은 방식이란 어떤 시점에서 콜백을 호출할지, 인자에는 어떤 값들을 지정할지, this에 무엇을 바인딩할지 등이다.

**주의할 점**

콜백함수도 “함수”이다.

```jsx
let arr = [1, 2, 3, 4, 5];
let obj = {
  vals: [1, 2, 3],
  logValues: function (v, i) {
    if (this.vals) {
      console.log(this.vals, v, i);
    } else {
      console.log(this, v, i);
    }
  },
};

obj.logValues(1, 2);
arr.forEach(obj.logValues);
```

.앞에 있는 객체가 this가 된다고 배웠다. 이건 메서드로서의 함수 호출에서는 올바른 예측이다.

하지만 forEach()는 첫 번째 인자로 콜백 함수를 넘겨 받는데 obj.logValues를 넘겨주었다.

.앞에 obj 객체가 있으니 메서드로서의 호출이지 않나 싶지만 콜백함수도 “함수”이기 때문에

함수로서의 호출을 한 셈이 된다. 3장 this에서 배운 것처럼 **함수로서의 호출은 무조건 전역객체를 가르킨다.** 그래서 여기서 arr.forEach(obj.values)도 전역객체를 가르키고 있다.

**헷갈리지 않도록 주의하자!**

```jsx
let apple = ["아이폰", "아이패드", "맥북프로", "애플워치"];
let index = 0;

function appleFunc() {
  if (index < apple.length) {
    console.log(apple[index]);
    index++;
  } else {
    clearInterval(timer);
  }
}

let timer = setInterval(appleFunc, 2000);
```

- 위 예제 코드에서는 2초마다 appleFunc함수를 호출한다.
- appleFunc함수는 index를 1씩 증가시키면서 apple 배열의 길이만큼 반복하고 종료된다.
- 결과는 2초마다 apple 배열 안에 있는 값이 출력된다.

setInterval이라는 `다른코드` 에 첫 번째 인자로 appleFunc 함수를 넘겨주자 제어권을 받은 setInterval이 두 번째 인자로 받은 delay값 마다

appleFunc함수를 실행했다.

이처럼 콜백 함수의 제어권을 넘겨받은 코드는 콜백 함수 호출 시점에 대한 제어권을 가지게 된다.

### 콜백 함수 내부의 this에 다른 값 바인딩하기

```jsx
let obj = {
  name: "이만재",
  func: function () {
    console.log(this.name);
  },
};

setTimeout(obj.func.bind(obj), 1000);

let obj2 = { name: "이만재2" };

setTimeout(obj.func.bind(obj2), 2000);
```

3장에서 배운 것처럼 bind 메서드를 사용해 this를 이걸로 할게라고 해주면 된다!

### 콜백 지옥

콜백지옥이란 콜백함수를 익명함수로 전달하는 과정이 반복되면서 코드의 들여쓰기가 엄청 깊어지는 것을 의미한다. 이렇게 될 경우 코드의 가독성이 떨어질 뿐만 아니라 수정 역시 어려워진다.

```jsx
setTimeout(
  function (name) {
    let coffeeList = name;
    console.log(coffeeList);

    setTimeout(
      function (name) {
        coffeeList += ", " + name;
        console.log(coffeeList);

        setTimeout(
          function (name) {
            coffeeList += ", " + name;
            console.log(coffeeList);

            setTimeout(
              function (name) {
                coffeeList += ", " + name;
                console.log(coffeeList);
              },
              500,
              "카페라떼"
            );
          },
          500,
          "카페모카"
        );
      },
      500,
      "아메리카노"
    );
  },
  500,
  "에스프레소"
);
```

위 코드가 콜백지옥의 예시이다.

값이 전달되는 순서가 아래에서 위로 향하고 있어 보기에도 좋지 않고 어색하게 느껴진다.

```jsx
let coffeeList = " ";

let addExpresso = function (name) {
  coffeeList = name;
  console.log(coffeeList);
  setTimeout(addAmericano, 500, "아메리카노");
};

let addAmericano = function (name) {
  coffeeList = name;
  console.log(coffeeList);
  setTimeout(addMocha, 500, "카페모카");
};

let addMocha = function (name) {
  coffeeList = name;
  console.log(coffeeList);
  setTimeout(addLatte, 500, "카페라떼");
};

let addLatte = function (name) {
  coffeeList = name;
  console.log(coffeeList);
};

setTimeout(addExpresso, 500, "에스프레소");
```

위 코드는 `기명함수`를 사용해 콜백 지옥을 해결한 예시이다.

한눈에 봐도 코드 가독성이 더 좋아진 것을 알 수 있다.

2장 실행 컨텍스트에서 `익명함수`를 조금 설명한 적이 있다.

### 이름없는 함수와 기명함수의 차이점

일단 이름없는 함수가 뭐고 기명함수가 뭔지 알아보자

```jsx
let func = function(){
	console.log("나는 익명함수라고해")
}

function nameFunc(){
	console.log("나는 기명함수라고해")
}

func()
nameFunc()

//실행결과
나는 익명함수라고해
나는 기명함수라고해
```

1. **이름:**
   - 기명함수는 이름이 있고, 이 이름을 통해 함수를 호출한다.
   - 익명함수는 이름이 없고, 변수에 할당하거나 다른 함수의 인수로 전달된다.(콜백함수)
2. **호이스팅:**
   - 기명 함수는 호이스팅 되어 함수 선언 이전에 호출할 수 있다.
   - 익명 함수는 변수에 할당된 후에만 호출할 수 있다.

---

**2장 실행컨텍스트에서 호이스팅이 어떻게 이루어지는지에 대한 설명에서도 나왔던 부분이다.**

**호이스팅이 될 때 함수는 함수자체가 호이스팅 되지만 변수는 선언만 호이스팅 된다고 배웠다.**

**그렇다면 우리는 여기서 한가지 알 수 있는 사실이 있다.**

**익명함수는 변수에 할당되기 때문에 호이스팅이 일어날 때 `선언만 호이스팅 되지만`**

**기명함수는 `함수 자체가 호이스팅 된다.`**

---

```jsx
nameFunc()

function nameFunc(){
	console.log("나는 기명함수라고해")
}

//실행결과
나는 기명함수라고해
```

```jsx
func()

(var, let, const) func = function(){
	console.log("나는 익명함수라고해")
}

//실행결과
var의 경우: func is not a function
let, const의 경우: ReferenceError: Cannot access 'func' before initialization
```

위 예시 코드들 처럼 기명함수의 경우 함수자체가 호이스팅 되기 때문에 console문이 출력된다.

하지만 익명함수의 경우는 동작이 다르다.

- var의 경우 var func = undefined인 상태일 것이다.(var는 선언과 동시에 undefined로 초기화 하기 때문)
- var의 경우 동작 확인

```jsx
console.log(func);

var func = function () {
  console.log("나는 이름없는 함수라고해");
};

//실행결과
undefined;
```

- let과 const의 경우 ReferenceError: Cannot access 'func' before initialization 이런 에러문이 출력된다.
- let과 const는 var와 다르게 TDZ가 존재하기 때문에 초기화 전에 접근할 수없다는 에러가 나온다.

---

1. 사용용도:

   - 기명함수는 주로 독립적인 함수로 사용된다.
   - 익명함수는 주로 콜백함수, 즉시 실행 함수(IIFE), 또는 변수에 할당되어 사용된다.
   - IIFE(Immediately Invoked Function Expression)란 정의와 동시에 즉시 실행되는 함수라는 의미이다.

   ```jsx
   (function () {
       console.log("나는 익명함수인데 즉시 실행 함수야");
     })();

     //실행결과
     나는 익명함수인데 즉시 실행 함수야
   ```

2. **디버깅:**
   - 기명함수는 이름이 있기 때문에 디버깅 시 콜 스택에서 쉽게 식별할 수 있다.
   - 익명함수는 이름이 없기 때문에 디버깅 시 식별이 어려울 수 있지만 변수명이나, 코드 컨텍스트를 통해 추적할 수 있다.

### Promise

자바스크립트에서 **Promise는 비동기 작업의 완료 또는 실패를 나타내는 객체이다.**

**Promise 객체는** **3가지 상태를 가진다.**

1. 대기(pending): 초기상태이며 이행도 거부도 되지 않은 상태
2. 이행(fulfilled): 작업이 성공적으로 완료되어 약속을 이행한 상태
3. 거부(rejected): 작업이 실패한 상태

```jsx
let promise = new Promise(function (resolve, reject) {
  let success = true;

  if (success) {
    resolve("작업 성공");
  } else {
    reject("작업 실패");
  }
});
```

다른 스터디원들은 어떨지 모르겠지만 나는 Promise에 대해 아는 것이 없었다. 들어보기만 했지 실제로 이렇게 찾아보며 공부한 적이 없었기 때문이다.

그래서 예제를 찾아보면서 new Promise(function (resolve, reject)) 부분을 보고

promise()라고 작성하고 실행하니 promise는 함수가 아니라는 에러문을 만났다.

사실 당연했다. Promise는 객체이지 함수가 아니기 때문이다,,, 그렇다면 작업성공이라는 출력문은 어떻게 하면 출력이되는가? 라는 궁금증을 해결하기 위해 찾아본 결과!!

Promise 객체 자체는 생성된 순간 바로 실행된다. new Promise 구문이 실행되는 즉시 전달된 함수(실행자 함수 또는 executor)가 실행된다. 그 후 콜백함수로 resolve 또는 reject가 즉시 호출된다.

위 코드는 Promise 객체가 생성된 것 뿐이지 작업에 대한 결과를 처리해 주진 않았다.

Promise 객체는 비동기 작업의 결과를 나타내기 때문에 `then 또는 catch 메서드를 사용해 결과를 처리해주어야 했다.`

```jsx
let promise = new Promise(function (resolve, reject) {
  let success = true;

  if (success) {
    resolve("작업 성공");
  } else {
    reject("작업 실패");
  }
});

promise
  .then(function (result) {
    console.log(result);
  })
  .catch(function (error) {
    console.log(error);
  });
```

위 코드는 then과 catch 메서드를 사용해 비동기 작업에 대한 결과를 처리해준 예시 코드이다.

이제 코드의 동작을 한 번 따라가보도록 하겠다.

1. **Promise 객체 생성**

- Promise 객체가 생성된다.
- 실행자 함수가 “즉시” 실행된다.

```jsx
let promise = new Promise(function (resolve, reject) {
  let success = true;

  if (success) {
    resolve("작업 성공");
  } else {
    reject("작업 실패");
  }
});

------------------------
{
let success = true;

  if (success) {
    resolve("작업 성공");
  } else {
    reject("작업 실패");
  }
}
------------------------

{} 안에 있는 코드 부분이 실행자 함수 부분이다.
```

- success 변수가 true로 설정된다.
- if(success) 조건이 true이기 때문에 resolve(”작업 성공”)이 호출된다.
- 이때 Promise 객체는 “이행(fulfilled)” 상태가 된다.

1. then과 catch 메서드 등록

- catch 메서드는 Promise가 “거부(rejected)” 상태가 되었을 때 호출될 콜백함수를 등록한다.
  이 경우 “이행(fulfilled)” 상태이기 때문에 이 콜백함수는 호출되지 않는다.
- then 메서드는 Promise가 “이행(fulfilled)” 상태가 되었을 때 호출될 콜백함수를 등록한다.

1. Promise 상태 전환 및 콜백 실행

- resolve(”작업 성공”)이 호출되어 “이행(fulfilled)” 상태가 된다.
- Promise의 상태가 “이행(fulfilled)” 변경되면 then 메서드에 등록된 콜백함수가 호출된다.
- then 메서드의 콜백함수는 console.log(result)를 실행한다.
  이때 result는 resolve 함수에서 전달된 “작업 성공” 이다.
- 콘솔에 작업성공이 출력된다.

### then, catch와 try, catch의 목적성의 차이점

Promise에 대해서 찾아보면서 then, catch와 try, catch 이름이 비슷해서 같은 동작을 하는건가? 라는 생각이 들었다. 이 둘은 비슷한 목적을 가지고 있는 것은 맞지만 사용되는 맥락과 동작 방식에 있어서 차이가 있다는 것을 알게되었고 이번 기회에 차이점을 이해하고 정리해보도록 하겠다!!

**비동기와 동기란?**

- 동기 코드: 순서대로 실행되며, 이전 작업이 완료되지 않으면 다음 작업이 시작되지 않는다.
- 비동기 코드: 특정 작업이 완료될 때까지 기다리지 않고, 다음 작업이 즉시 실행된다. 비동기 작업의 결과는 나중에 콜백함수를 통해 처리된다.
- 비동기 코드의 동작

```jsx
let promise = new Promise(function (resolve, reject) {
  setTimeout(() => {
    let success = true;
    if (success) {
      resolve("작업 성공");
    } else {
      reject("작업 실패");
    }
  }, 1000);
});

promise
  .then(function (result) {
    console.log(result);
  })
  .catch(function (error) {
    console.log(error);
  });

console.log("이 코드는 비동기 작업 완료를 기다리지 않고 바로 실행된다.");

//실행결과
이 코드는 비동기 작업 완료를 기다리지 않고 바로 실행된다.
작업 성공
```

- 동기 코드의 동작

```jsx
function syncFunction() {
  console.log("첫 번째 작업 시작");
  let result = 1 + 1; // 동기 작업
  console.log("첫 번째 작업 완료, 결과:", result);

  console.log("두 번째 작업 시작");
  result = 2 + 2; // 동기 작업
  console.log("두 번째 작업 완료, 결과:", result);
}

console.log("프로그램 시작");
syncFunction();
console.log("프로그램 종료");

//실행결과
프로그램 시작
첫 번째 작업 시작
첫 번째 작업 완료, 결과: 2
두 번째 작업 시작
두 번째 작업 완료, 결과: 4
프로그램 종료
```

**then 메서드(비동기 작업 처리)**

- **목적:** 비동기 작업의 결과를 처리하기 위해 사용된다. 비동기 작업이 끝난 후, 성공하거나 실패했을 때의 어떤 동작을 할지 정할 수 있다.
- **동작:**
  1. then메서드는 비동기 작업을 수행한 Promise 객체에서 호출된다.
  2. 작업이 성공하면 then의 첫 번째 함수가 실행되고, 실패하면 두 번째 함수(선택사항)가 실행된다.
  ```jsx
  let macBookOrder = new Promise(function (resolve, reject) {
    let success = false;

    if (success) {
      resolve("주문하신 맥북프로가 지금 문 앞에 도착했어요!");
    } else {
      reject("주문하신 맥북프로를 배달하다가 도난당했어요!");
    }
  });

  macBookOrder.then(
    function (message) {
      console.log(message);
    },
    function (error) {
      console.log(error);
    }
  );
  ```

위 예시코드처럼 then의 두 번째 함수를 지정해 비동기 작업의 실패했을 때를 처리할 수 있다.

하지만 우리는 지금까지 then, catch만 사용했을 것이다. 이유는 다음과 같다.

1. **가독성:**
   - catch 메서드를 사용하면 실패 퍼리가 더 명확하게 분리되기 때문에 가독성이 좋아진다.
   - 아마 then메서드의 두 번째 함수를 통해 비동기 작업의 실패를 처리할 수 있다는 것은 다들 처음 알게되었을 것이다. 이 사실을 모르고 위 예시 코드를 봤으면 왜 catch 메서드가 없지? 하는 의문점을 가지게 되었을 것이다.
2. 체이닝:

   - catch 메서드는 then 메서드와 마찬가지로 체이닝이 가능하다. 여러 비동기 작업이 연결된 경우, catch 메서드는 체이닝의 마지막에 두어 모든 실패를 한 번에 처리할 수 있다.
   - then 메서드의 두 번째 인수로 실패 처리를 하면 각 “then” 메서드마다 실패 처리를 해주어야 하기 때문에 코드가 복잡해질 수 있다.
   - then 메서드로 실패를 처리했을 경우

   ```jsx
   function newMacBookOrder() {
     return new Promise(function (resolve, reject) {
       let success = Math.floor(Math.random() * 10) + 1;

       if (success % 2 === 0) {
         resolve("주문하신 맥북프로가 지금 문 앞에 도착했어요!");
       } else {
         reject("주문하신 맥북프로를 배달하다가 도난당했어요!");
       }
     });
   }

   let macBookOrder = newMacBookOrder();

   macBookOrder
     .then(
       function (message) {
         console.log("첫 번째 주문 성공:", message);
         return newMacBookOrder();
       },
       function (error) {
         console.log("첫 번째 주문 실패:", error);
         return newMacBookOrder();
       }
     )
     .then(
       function (message) {
         console.log("두 번째 주문 성공:", message);
         return newMacBookOrder();
       },
       function (error) {
         console.log("두 번째 주문 실패:", error);
         return newMacBookOrder();
       }
     )
     .then(
       function (message) {
         console.log("세 번째 주문 성공:", message);
       },
       function (error) {
         console.log("세 번째 주문 실패:", error);
       }
     );
   ```

- catch 메서드를 사용해 실패를 처리한 경우

```jsx
function newMacBookOrder() {
  return new Promise(function (resolve, reject) {
    let success = Math.floor(Math.random() * 10) + 1;

    if (success % 2 === 0) {
      resolve("주문하신 맥북프로가 지금 문 앞에 도착했어요!");
    } else {
      reject("주문하신 맥북프로를 배달하다가 도난당했어요!");
    }
  });
}

let macBookOrder = newMacBookOrder();

macBookOrder
  .then(function (message) {
    console.log("첫 번째 주문 성공:", message);
    return newMacBookOrder();
  })
  .then(function (message) {
    console.log("두 번째 주문 성공:", message);
    return newMacBookOrder();
  })
  .then(function (message) {
    console.log("세 번째 주문 성공:", message);
  })
  .catch(function (error) {
    console.log("주문 실패", error);
  });
```

**try 블록(동기 코드에서의 예외처리)**

- **목적:** 코드가 실행될 때 발생할 수 있는 오류를 잡아서 처리하는데 사용된다.
- 동작:
  1. try 블록 안의 코드가 실행되다가 오류가 발생하면 “catch” 블록으로 제어가 넘어간다.
  2. catch 블록은 발생한 오류를 처리하고 finally 블록(있다면)은 `오류 발생 여부와 상관없이 항상 실행된다.`

### 핵심 차이점

- **then**
  - **비동기:** 웹사이트에서 데이터를 요청할 때처럼, 작업이 끝나고 결과를 처리한다.
  - **사용법:** 비동기 작업의 성공 또는 실패를 다루기 위해 사용한다.
- **try**
  - **동기:** 코드가 실행되는 동안 발생할 수 있는 오류를 처리한다.
  - **사용법:** 코드가 실행되는 동안 예상치 못한 오류를 처리하기 위해 사용한다.

### try블록에서의 catch와 then메서드의 catch 차이점

- **공통점**

  - 둘 다 오류가 발생했을 때 그 오류를 처리하기 위해 사용된다.
  - 둘 다 오류처리 코드를 작성하는 부분이다.

- **차이점**
  - **비동기 vs 동기:** **then의 catch**는 비동기 작업의 오류를 처리하는데 사용되고, **try의 catch**는 동기 코드의 오류를 처리하는데 사용된다.
  - **작동방식:** **then의 catch**는 Promise의 오류를 잡아내고 **try의 catch**는 코드 블록 내의 모든 오류를 잡아낸다.
